<?xml version="1.0" encoding="UTF-8"?>
<!-- Generated by org.testng.reporters.JUnitXMLReporter -->
<testsuite ignored="0" hostname="AWS-PVDI-6" failures="1" tests="2" name="Default test" time="13.451" errors="0" timestamp="2024-01-05T09:47:37 IST">
  <testcase classname="io.cucumber.testng.AbstractTestNGCucumberTests" name="runScenario" time="6.252"/>
  <testcase classname="io.cucumber.testng.AbstractTestNGCucumberTests" name="runScenario" time="2.85">
    <failure type="java.lang.Exception" message="Exception occured">
      <![CDATA[java.lang.Exception: Exception occured
at stepdefinitions.TestClass.navigate_to_url_feature_two(TestClass.java:13)
at âœ½.navigate to URL feature two(file:///C:/Users/ININDC00076/git/ULS_IjarahAnandh_ULS/AzentioAutomationFramework_AnandhULS/src/test/java/features/snippets/FeatureFile01.feature:5)
]]>
    </failure>
  </testcase> <!-- runScenario -->
</testsuite> <!-- Default test -->
